Workbook

Sheet Loan
A1: عنوان | B1: مبلغ قسط | C1: تعداد اقساط | D1: تاریخ شروع | E1: تاریخ پایان | F1: روز قسط در ماه | G1: وضعیت
A2: مهر ایران | B2: 8860000 | C2: 24 | D2: 1404-07-30 | E2: 1406-07-30 | F2: 1 | G2: در جریان
A3: مهر ایران | B3: 13640000 | C3: 24 | D3: 1402-06-30 | E3: 1404-06-30 | F3: 1 | G3: تمام شده
A4: ملی | B4: 27000000 | C4: 36 | D4: 1402-06-30 | E4: 1405-06-30 | F4: 1 | G4: در جریان
A5: اجاره | B5: 30000000 | C5: 12 | D5: 1404-06-30 | E5: 1405-06-30 | F5: 1 | G5: در جریان
A6: ملت | B6: 16363000 | C6: 120 | D6: 1402-06-22 | E6: 1412-06-22 | F6: 1 | G6: در جریان
A7: رسالت | B7: 40000000 | C7: 20 | D7: 1403-05-06 | E7: 1405-01-06 | F7: 6 | G7: در جریان
A8: رسالت | B8: 30000000 | C8: 18 | D8: 1402-11-08 | E8: 1404-05-08 | F8: 8 | G8: تمام شده
A9: آینده | B9: 32000000 | C9: 40 | D9: 1401-07-09 | E9: 1404-11-09 | F9: 9 | G9: در جریان
A10: رسالت | B10: 60000000 | E10: 1405-04-10 | F10: 10 | G10: در جریان
A11: شهر | B11: 50000000 | C11: 60 | D11: 1404-07-11 | E11: 1409-07-11 | F11: 11 | G11: در جریان
A12: اجاره | B12: 7500000 | C12: 12 | D12: 1404-06-15 | E12: 1405-06-15 | F12: 15 | G12: در جریان
A13: رسالت | B13: 4500000 | C13: 10 | D13: 1403-06-17 | E13: 1404-04-17 | F13: 17 | G13: تمام شده
A14: رسالت | B14: 22000000 | C14: 10 | D14: 1404-03-22 | E14: 1405-01-22 | F14: 22 | G14: در جریان
A15: رسالت | B15: 70000000 | C15: 15 | D15: 1403-10-27 | E15: 1404-12-27 | F15: 27 | G15: در جریان
A16: دایی | B16: 60000000 | F16: 15 | G16: در جریان
A17: بابا | B17: 60000000 | F17: 15 | G17: در جریان
A18: صندق ماشین ظرف شویی | B18: 40000000 | C18: 10 | D18: 1404-06-01 | E18: 1404-04-01 | F18: 1 | G18: در جریان

Sheet Installments
A1: 1404 | B1: ملت | C1: مهر ایران | D1: ملی | E1: رسالت | F1: رسالت | G1: رسالت | H1: آینده | I1: صندوق ها | J1: بابا | K1: دایی | L1: اجاره | M1: بیمه ماشین | N1: اسنپ و تپسی | O1: قسط ریحانه | P1: اجاره پارکینگ | Q1: رسالت ماشین | R1: شهر | T1: مجموع | U1: علیرضا | V1: ریحانه
A2: فرودین | B2: 16363000 | C2: 13640000 | D2: 27000000 | E2: 4500000 | F2: 40000000 | G2: 30000000 | H2: 32000000 | I2: 65000000 | J2: 50000000 | K2: 60000000 | L2: 60000000 | M2: 6500000 | N2: 20000000 | O2: 20000000 | P2: 7500000 | Q2: 70000000 | T2: =SUM(B2:Q2) -> 522503000 | U2: =SUM(Q2,P2,M2,L2,K2,J2,H2,G2,F2,E2,D2,C2,B2) -> 417503000 | V2: =SUM(O2,N2,I2) -> 105000000
A3: اردیبهشت | B3: 16363000 | C3: 13640000 | D3: 27000000 | E3: 4500000 | F3: 40000000 | G3: 30000000 | H3: 32000000 | I3: 65000000 | J3: 50000000 | K3: 60000000 | L3: 60000000 | M3: 6500000 | N3: 20000000 | O3: 20000000 | P3: 7500000 | Q3: 70000000 | T3: =SUM(B3:Q3) -> 522503000 | U3: =SUM(Q3,P3,M3,L3,K3,J3,H3,G3,F3,E3,D3,C3,B3) -> 417503000 | V3: =SUM(O3,N3,I3) -> 105000000
A4: خرداد | B4: 16363000 | C4: 13640000 | D4: 27000000 | E4: 4500000 | F4: 40000000 | G4: 30000000 | H4: 32000000 | I4: 65000000 | J4: 50000000 | K4: 60000000 | L4: 60000000 | M4: 6500000 | N4: 20000000 | O4: 20000000 | P4: 7500000 | Q4: 70000000 | T4: =SUM(B4:Q4) -> 522503000 | U4: =SUM(Q4,P4,M4,L4,K4,J4,H4,G4,F4,E4,D4,C4,B4) -> 417503000 | V4: =SUM(O4,N4,I4) -> 105000000
A5: تیر | B5: 16363000 | C5: 13640000 | D5: 27000000 | E5: 4500000 | F5: 40000000 | G5: 30000000 | H5: 32000000 | I5: 65000000 | J5: 50000000 | K5: 60000000 | L5: 60000000 | M5: 6500000 | N5: 20000000 | O5: 20000000 | P5: 7500000 | Q5: 70000000 | T5: =SUM(B5:Q5) -> 522503000 | U5: =SUM(Q5,P5,M5,L5,K5,J5,H5,G5,F5,E5,D5,C5,B5) -> 417503000 | V5: =SUM(O5,N5,I5) -> 105000000
A6: مرداد | B6: 16363000 | C6: 13640000 | D6: 27000000 | E6: 0 | F6: 40000000 | G6: 30000000 | H6: 32000000 | I6: 65000000 | J6: 50000000 | K6: 60000000 | L6: 60000000 | M6: 6500000 | N6: 20000000 | O6: 20000000 | P6: 7500000 | Q6: 70000000 | T6: =SUM(B6:Q6) -> 518003000 | U6: =SUM(Q6,P6,M6,L6,K6,J6,H6,G6,F6,E6,D6,C6,B6) -> 413003000 | V6: =SUM(O6,N6,I6) -> 105000000
A7: شهریور | B7: 16363000 | C7: 13640000 | D7: 27000000 | E7: 0 | F7: 40000000 | G7: 0 | H7: 32000000 | I7: 25000000 | J7: 50000000 | K7: 60000000 | L7: 30000000 | M7: 6500000 | N7: 32000000 | O7: 20000000 | P7: 7500000 | Q7: 70000000 | T7: =SUM(B7:R7) -> 430003000 | U7: =SUM(Q7,P7,M7,L7,K7,J7,H7,G7,F7,E7,D7,C7,B7,R7) -> 353003000 | V7: =SUM(O7,N7,I7) -> 77000000
A8: مهر | B8: 57600000 | C8: 17540000 | D8: 27000000 | E8: 62000000 | F8: 40000000 | G8: 0 | H8: 32000000 | I8: 25000000 | J8: 50000000 | K8: 60000000 | L8: 30000000 | M8: 6500000 | N8: 32000000 | O8: 20000000 | P8: 7500000 | Q8: 70000000 | R8: 97000000 | T8: =SUM(B8:R8) -> 634140000 | U8: =SUM(Q8,P8,M8,L8,K8,J8,H8,G8,F8,E8,D8,C8,B8,R8) -> 557140000 | V8: =SUM(O8,N8,I8) -> 77000000
A9: آبان | B9: 16363000 | C9: 22500000 | D9: 27000000 | E9: 62000000 | F9: 40000000 | G9: 0 | H9: 32000000 | I9: 0 | J9: 50000000 | K9: 60000000 | L9: 30000000 | M9: 6500000 | N9: 32000000 | O9: 20000000 | P9: 7500000 | Q9: 70000000 | R9: 51000000 | T9: =SUM(B9:R9) -> 526863000 | U9: =SUM(Q9,P9,M9,L9,K9,J9,H9,G9,F9,E9,D9,C9,B9,R9) -> 474863000 | V9: =SUM(O9,N9,I9) -> 52000000
A10: آذر | B10: 16363000 | C10: 22500000 | D10: 27000000 | E10: 62000000 | F10: 40000000 | G10: 0 | H10: 32000000 | I10: 0 | J10: 50000000 | K10: 60000000 | L10: 30000000 | M10: 6500000 | N10: 20000000 | O10: 20000000 | P10: 7500000 | Q10: 70000000 | R10: 51000000 | T10: =SUM(B10:R10) -> 514863000 | U10: =SUM(Q10,P10,M10,L10,K10,J10,H10,G10,F10,E10,D10,C10,B10,R10) -> 474863000 | V10: =SUM(O10,N10,I10) -> 40000000
A11: دی | B11: 16363000 | C11: 22500000 | D11: 27000000 | E11: 62000000 | F11: 40000000 | G11: 0 | H11: 32000000 | I11: 0 | J11: 50000000 | K11: 60000000 | L11: 30000000 | M11: 6500000 | N11: 20000000 | O11: 20000000 | P11: 7500000 | Q11: 70000000 | R11: 51000000 | T11: =SUM(B11:R11) -> 514863000 | U11: =SUM(Q11,P11,M11,L11,K11,J11,H11,G11,F11,E11,D11,C11,B11,R11) -> 474863000 | V11: =SUM(O11,N11,I11) -> 40000000
A12: بهمن | B12: 16363000 | C12: 22500000 | D12: 27000000 | E12: 62000000 | F12: 40000000 | G12: 0 | H12: 32000000 | I12: 0 | J12: 50000000 | K12: 60000000 | L12: 30000000 | M12: 6500000 | N12: 20000000 | O12: 20000000 | P12: 7500000 | Q12: 70000000 | R12: 51000000 | T12: =SUM(B12:R12) -> 514863000 | U12: =SUM(Q12,P12,M12,L12,K12,J12,H12,G12,F12,E12,D12,C12,B12,R12) -> 474863000 | V12: =SUM(O12,N12,I12) -> 40000000
A13: اسفند | B13: 16363000 | C13: 22500000 | D13: 27000000 | E13: 62000000 | F13: 40000000 | G13: 0 | H13: 0 | I13: 0 | J13: 50000000 | K13: 60000000 | L13: 30000000 | M13: 0 | N13: 20000000 | O13: 20000000 | P13: 7500000 | Q13: 70000000 | R13: 51000000 | T13: =SUM(B13:R13) -> 476363000 | U13: =SUM(Q13,P13,M13,L13,K13,J13,H13,G13,F13,E13,D13,C13,B13,R13) -> 436363000 | V13: =SUM(O13,N13,I13) -> 40000000
A16: 1405 | B16: ملت | C16: مهر ایران | D16: ملی | E16: رسالت | F16: رسالت | G16: رسالت | H16: آینده | I16: صندوق ها | J16: بابا | K16: دایی | L16: اجاره | M16: بیمه ها | N16: اسنپ و تپسی | O16: قسط ریحانه | P16: اجاره پارکینگ | Q16: رسالت | R16: شهر
A17: فرودین | B17: 16363000 | C17: 22500000 | D17: 27000000 | E17: 62000000 | F17: 40000000 | G17: 0 | H17: 0 | I17: 0 | J17: 50000000 | K17: 60000000 | L17: 30000000 | M17: 0 | N17: 20000000 | O17: 20000000 | P17: 7500000 | Q17: 70000000 | R17: 51000000 | T17: =SUM(B17:R17) -> 476363000 | U17: =SUM(Q17,P17,M17,L17,K17,J17,H17,G17,F17,E17,D17,C17,B17,R17) -> 436363000 | V17: =SUM(O17,N17,I17) -> 40000000
A18: اردیبهشت | B18: 16363000 | C18: 22500000 | D18: 27000000 | E18: 62000000 | F18: 0 | G18: 0 | H18: 0 | I18: 0 | J18: 50000000 | K18: 60000000 | L18: 30000000 | M18: 0 | N18: 20000000 | O18: 20000000 | P18: 7500000 | Q18: 0 | R18: 51000000 | T18: =SUM(B18:R18) -> 366363000 | U18: =SUM(Q18,P18,M18,L18,K18,J18,H18,G18,F18,E18,D18,C18,B18,R18) -> 326363000 | V18: =SUM(O18,N18,I18) -> 40000000
A19: خرداد | B19: 16363000 | C19: 22500000 | D19: 27000000 | E19: 62000000 | F19: 0 | G19: 0 | H19: 0 | I19: 0 | J19: 50000000 | K19: 60000000 | L19: 30000000 | M19: 0 | N19: 20000000 | O19: 20000000 | P19: 7500000 | Q19: 0 | R19: 51000000 | T19: =SUM(B19:R19) -> 366363000 | U19: =SUM(Q19,P19,M19,L19,K19,J19,H19,G19,F19,E19,D19,C19,B19,R19) -> 326363000 | V19: =SUM(O19,N19,I19) -> 40000000
A20: تیر | B20: 16363000 | C20: 22500000 | D20: 27000000 | E20: 62000000 | F20: 0 | G20: 0 | H20: 0 | I20: 0 | J20: 50000000 | K20: 60000000 | L20: 30000000 | M20: 0 | N20: 20000000 | O20: 20000000 | P20: 7500000 | Q20: 0 | R20: 51000000 | T20: =SUM(B20:R20) -> 366363000 | U20: =SUM(Q20,P20,M20,L20,K20,J20,H20,G20,F20,E20,D20,C20,B20,R20) -> 326363000 | V20: =SUM(O20,N20,I20) -> 40000000
A21: مرداد | B21: 16363000 | C21: 22500000 | D21: 27000000 | E21: 0 | F21: 0 | G21: 0 | H21: 0 | I21: 0 | J21: 50000000 | K21: 60000000 | L21: 30000000 | M21: 0 | N21: 20000000 | O21: 20000000 | P21: 7500000 | Q21: 0 | R21: 51000000 | T21: =SUM(B21:R21) -> 304363000 | U21: =SUM(Q21,P21,M21,L21,K21,J21,H21,G21,F21,E21,D21,C21,B21,R21) -> 264363000 | V21: =SUM(O21,N21,I21) -> 40000000
A22: شهریور | B22: 16363000 | C22: 22500000 | D22: 27000000 | E22: 0 | F22: 0 | G22: 0 | H22: 0 | I22: 0 | J22: 50000000 | K22: 60000000 | L22: 30000000 | M22: 0 | N22: 20000000 | O22: 20000000 | P22: 7500000 | Q22: 0 | R22: 51000000 | T22: =SUM(B22:R22) -> 304363000 | U22: =SUM(Q22,P22,M22,L22,K22,J22,H22,G22,F22,E22,D22,C22,B22,R22) -> 264363000 | V22: =SUM(O22,N22,I22) -> 40000000
A23: مهر | B23: 50400000 | C23: 17540000 | D23: 0 | E23: 0 | F23: 0 | G23: 0 | H23: 0 | I23: 0 | J23: 50000000 | K23: 60000000 | L23: 30000000 | M23: 0 | N23: 20000000 | O23: 20000000 | P23: 7500000 | Q23: 0 | R23: 51000000 | T23: =SUM(B23:R23) -> 306440000 | U23: =SUM(Q23,P23,M23,L23,K23,J23,H23,G23,F23,E23,D23,C23,B23,R23) -> 266440000 | V23: =SUM(O23,N23,I23) -> 40000000
A24: آبان | B24: 16363000 | C24: 22500000 | D24: 0 | E24: 0 | F24: 0 | G24: 0 | H24: 0 | I24: 0 | J24: 50000000 | K24: 60000000 | L24: 30000000 | M24: 0 | N24: 20000000 | O24: 20000000 | P24: 7500000 | Q24: 0 | R24: 51000000 | T24: =SUM(B24:R24) -> 277363000 | U24: =SUM(Q24,P24,M24,L24,K24,J24,H24,G24,F24,E24,D24,C24,B24,R24) -> 237363000 | V24: =SUM(O24,N24,I24) -> 40000000
A25: آذر | B25: 16363000 | C25: 22500000 | D25: 0 | E25: 0 | F25: 0 | G25: 0 | H25: 0 | I25: 0 | J25: 50000000 | K25: 60000000 | L25: 30000000 | M25: 0 | N25: 20000000 | O25: 20000000 | P25: 7500000 | Q25: 0 | R25: 51000000 | T25: =SUM(B25:R25) -> 277363000 | U25: =SUM(Q25,P25,M25,L25,K25,J25,H25,G25,F25,E25,D25,C25,B25,R25) -> 237363000 | V25: =SUM(O25,N25,I25) -> 40000000
A26: دی | B26: 16363000 | C26: 22500000 | D26: 0 | E26: 0 | F26: 0 | G26: 0 | H26: 0 | I26: 0 | J26: 0 | K26: 60000000 | L26: 30000000 | M26: 0 | N26: 20000000 | O26: 20000000 | P26: 7500000 | Q26: 0 | R26: 51000000 | T26: =SUM(B26:R26) -> 227363000 | U26: =SUM(Q26,P26,M26,L26,K26,J26,H26,G26,F26,E26,D26,C26,B26,R26) -> 187363000 | V26: =SUM(O26,N26,I26) -> 40000000
A27: بهمن | B27: 16363000 | C27: 22500000 | D27: 0 | E27: 0 | F27: 0 | G27: 0 | H27: 0 | I27: 0 | J27: 0 | K27: 0 | L27: 30000000 | M27: 0 | N27: 20000000 | O27: 20000000 | P27: 7500000 | Q27: 0 | R27: 51000000 | T27: =SUM(B27:R27) -> 167363000 | U27: =SUM(Q27,P27,M27,L27,K27,J27,H27,G27,F27,E27,D27,C27,B27,R27) -> 127363000 | V27: =SUM(O27,N27,I27) -> 40000000
A28: اسفند | B28: 16363000 | C28: 22500000 | D28: 0 | E28: 0 | F28: 0 | G28: 0 | H28: 0 | I28: 0 | J28: 0 | K28: 0 | L28: 30000000 | M28: 0 | N28: 20000000 | O28: 20000000 | P28: 7500000 | Q28: 0 | R28: 51000000 | T28: =SUM(B28:R28) -> 167363000 | U28: =SUM(Q28,P28,M28,L28,K28,J28,H28,G28,F28,E28,D28,C28,B28,R28) -> 127363000 | V28: =SUM(O28,N28,I28) -> 40000000
A31: 1406 | B31: ملت | C31: مهر ایران | D31: ملی | E31: رسالت | F31: رسالت | G31: رسالت | H31: آینده | I31: صندوق ها | J31: بابا | K31: دایی | L31: اجاره | M31: بیمه ها | N31: اسنپ و تپسی | O31: قسط ریحانه | P31: اجاره پارکینگ | Q31: رسالت | R31: شهر
A32: فرودین | B32: 16363000 | C32: 22500000 | D32: 27000000 | E32: 0 | F32: 40000000 | G32: 0 | H32: 0 | I32: 0 | J32: 0 | K32: 0 | L32: 30000000 | M32: 0 | N32: 20000000 | O32: 20000000 | P32: 7500000 | R32: 51000000 | T32: =SUM(B32:R32) -> 234363000 | U32: =SUM(Q32,P32,M32,L32,K32,J32,H32,G32,F32,E32,D32,C32,B32,R32) -> 194363000 | V32: =SUM(O32,N32,I32) -> 40000000
A33: اردیبهشت | B33: 16363000 | C33: 22500000 | D33: 27000000 | E33: 0 | F33: 0 | G33: 0 | H33: 0 | I33: 0 | J33: 0 | K33: 0 | L33: 30000000 | M33: 0 | N33: 20000000 | O33: 20000000 | P33: 7500000 | Q33: 0 | R33: 51000000 | T33: =SUM(B33:R33) -> 194363000 | U33: =SUM(Q33,P33,M33,L33,K33,J33,H33,G33,F33,E33,D33,C33,B33,R33) -> 154363000 | V33: =SUM(O33,N33,I33) -> 40000000
A34: خرداد | B34: 16363000 | C34: 22500000 | D34: 27000000 | E34: 0 | F34: 0 | G34: 0 | H34: 0 | I34: 0 | J34: 0 | K34: 0 | L34: 30000000 | M34: 0 | N34: 20000000 | O34: 20000000 | P34: 7500000 | Q34: 0 | R34: 51000000 | T34: =SUM(B34:R34) -> 194363000 | U34: =SUM(Q34,P34,M34,L34,K34,J34,H34,G34,F34,E34,D34,C34,B34,R34) -> 154363000 | V34: =SUM(O34,N34,I34) -> 40000000
A35: تیر | B35: 16363000 | C35: 22500000 | D35: 27000000 | E35: 0 | F35: 0 | G35: 0 | H35: 0 | I35: 0 | J35: 0 | K35: 0 | L35: 30000000 | M35: 0 | N35: 20000000 | O35: 20000000 | P35: 7500000 | Q35: 0 | R35: 51000000 | T35: =SUM(B35:R35) -> 194363000 | U35: =SUM(Q35,P35,M35,L35,K35,J35,H35,G35,F35,E35,D35,C35,B35,R35) -> 154363000 | V35: =SUM(O35,N35,I35) -> 40000000
A36: مرداد | B36: 16363000 | C36: 22500000 | D36: 27000000 | E36: 0 | F36: 0 | G36: 0 | H36: 0 | I36: 0 | J36: 0 | K36: 0 | L36: 30000000 | M36: 0 | N36: 20000000 | O36: 20000000 | P36: 7500000 | Q36: 0 | R36: 51000000 | T36: =SUM(B36:R36) -> 194363000 | U36: =SUM(Q36,P36,M36,L36,K36,J36,H36,G36,F36,E36,D36,C36,B36,R36) -> 154363000 | V36: =SUM(O36,N36,I36) -> 40000000
A37: شهریور | B37: 16363000 | C37: 0 | D37: 27000000 | E37: 0 | F37: 0 | G37: 0 | H37: 0 | I37: 0 | J37: 0 | K37: 0 | L37: 30000000 | M37: 0 | N37: 20000000 | O37: 20000000 | P37: 7500000 | Q37: 0 | R37: 51000000 | T37: =SUM(B37:R37) -> 171863000 | U37: =SUM(Q37,P37,M37,L37,K37,J37,H37,G37,F37,E37,D37,C37,B37,R37) -> 131863000 | V37: =SUM(O37,N37,I37) -> 40000000
A38: مهر | B38: 43200000 | C38: 0 | D38: 0 | E38: 0 | F38: 0 | G38: 0 | H38: 0 | I38: 0 | J38: 0 | K38: 0 | L38: 30000000 | M38: 0 | N38: 20000000 | O38: 20000000 | P38: 7500000 | Q38: 0 | R38: 51000000 | T38: =SUM(B38:R38) -> 171700000 | U38: =SUM(Q38,P38,M38,L38,K38,J38,H38,G38,F38,E38,D38,C38,B38,R38) -> 131700000 | V38: =SUM(O38,N38,I38) -> 40000000
A39: آبان | B39: 16363000 | C39: 0 | D39: 0 | E39: 0 | F39: 0 | G39: 0 | H39: 0 | I39: 0 | J39: 0 | K39: 0 | L39: 30000000 | M39: 0 | N39: 20000000 | O39: 20000000 | P39: 7500000 | Q39: 0 | R39: 51000000 | T39: =SUM(B39:R39) -> 144863000 | U39: =SUM(Q39,P39,M39,L39,K39,J39,H39,G39,F39,E39,D39,C39,B39,R39) -> 104863000 | V39: =SUM(O39,N39,I39) -> 40000000
A40: آذر | B40: 16363000 | C40: 0 | D40: 0 | E40: 0 | F40: 0 | G40: 0 | H40: 0 | I40: 0 | J40: 0 | K40: 0 | L40: 30000000 | M40: 0 | N40: 20000000 | O40: 20000000 | P40: 7500000 | Q40: 0 | R40: 51000000 | T40: =SUM(B40:R40) -> 144863000 | U40: =SUM(Q40,P40,M40,L40,K40,J40,H40,G40,F40,E40,D40,C40,B40,R40) -> 104863000 | V40: =SUM(O40,N40,I40) -> 40000000
A41: دی | B41: 16363000 | C41: 0 | D41: 0 | E41: 0 | F41: 0 | G41: 0 | H41: 0 | I41: 0 | J41: 0 | K41: 0 | L41: 30000000 | M41: 0 | N41: 20000000 | O41: 20000000 | P41: 7500000 | Q41: 0 | R41: 51000000 | T41: =SUM(B41:R41) -> 144863000 | U41: =SUM(Q41,P41,M41,L41,K41,J41,H41,G41,F41,E41,D41,C41,B41,R41) -> 104863000 | V41: =SUM(O41,N41,I41) -> 40000000
A42: بهمن | B42: 16363000 | C42: 0 | D42: 0 | E42: 0 | F42: 0 | G42: 0 | H42: 0 | I42: 0 | J42: 0 | K42: 0 | L42: 30000000 | M42: 0 | N42: 20000000 | O42: 20000000 | P42: 7500000 | Q42: 0 | R42: 51000000 | T42: =SUM(B42:R42) -> 144863000 | U42: =SUM(Q42,P42,M42,L42,K42,J42,H42,G42,F42,E42,D42,C42,B42,R42) -> 104863000 | V42: =SUM(O42,N42,I42) -> 40000000
A43: اسفند | B43: 16363000 | C43: 0 | D43: 0 | E43: 0 | F43: 0 | G43: 0 | H43: 0 | I43: 0 | J43: 0 | K43: 0 | L43: 30000000 | M43: 0 | N43: 20000000 | O43: 20000000 | P43: 7500000 | Q43: 0 | R43: 51000000 | T43: =SUM(B43:R43) -> 144863000 | U43: =SUM(Q43,P43,M43,L43,K43,J43,H43,G43,F43,E43,D43,C43,B43,R43) -> 104863000 | V43: =SUM(O43,N43,I43) -> 40000000
A46: 1407 | B46: ملت | C46: مهر ایران | D46: ملی | E46: رسالت | F46: رسالت | G46: رسالت | H46: آینده | I46: صندوق ها | J46: بابا | K46: دایی | L46: اجاره | M46: بیمه ها | N46: اسنپ و تپسی | O46: قسط ریحانه | P46: اجاره پارکینگ | Q46: رسالت | R46: شهر
...

Sheet Income

Sheet Report
F1: 1404 | G1: علیرضا | H1: ریحانه | I1: سرمایه گزاری ثابت | J1: مکین | L1: مجموع درآمد | M1: مجموع هزینه | N1: مابه تفاوت | O1: ما به تفاوت علیرضا | P1: مابه تفاوت ریحانه
F2: فرودین | G2: 460000000 | H2: 238000000 | I2: 40000000 | J2: 140000000 | L2: =SUM(Report!G2:J2) -> 878000000 | M2: =SUM(Installments!B2:R2) -> 522503000 | N2: =L2-M2 -> 355497000 | O2: =Report!G2-Installments!U2 -> 42497000 | P2: =Report!H2-Installments!V2 -> 133000000
F3: اردیبهشت | G3: 460000000 | H3: 320000000 | I3: 40000000 | J3: 140000000 | L3: =SUM(Report!G3:J3) -> 960000000 | M3: =SUM(Installments!B3:R3) -> 522503000 | N3: =L3-M3 -> 437497000 | O3: =Report!G3-Installments!U3 -> 42497000 | P3: =Report!H3-Installments!V3 -> 215000000
F4: خرداد | G4: 460000000 | H4: 320000000 | I4: 40000000 | J4: 140000000 | L4: =SUM(Report!G4:J4) -> 960000000 | M4: =SUM(Installments!B4:R4) -> 522503000 | N4: =L4-M4 -> 437497000 | O4: =Report!G4-Installments!U4 -> 42497000 | P4: =Report!H4-Installments!V4 -> 215000000
F5: تیر | G5: 460000000 | H5: 320000000 | I5: 40000000 | J5: 0 | L5: =SUM(Report!G5:J5) -> 820000000 | M5: =SUM(Installments!B5:R5) -> 522503000 | N5: =L5-M5 -> 297497000 | O5: =Report!G5-Installments!U5 -> 42497000 | P5: =Report!H5-Installments!V5 -> 215000000
F6: مرداد | G6: 460000000 | H6: 320000000 | I6: 40000000 | J6: 0 | L6: =SUM(Report!G6:J6) -> 820000000 | M6: =SUM(Installments!B6:R6) -> 518003000 | N6: =L6-M6 -> 301997000 | O6: =Report!G6-Installments!U6 -> 46997000 | P6: =Report!H6-Installments!V6 -> 215000000
F7: شهریور | G7: 460000000 | H7: 370000000 | I7: 40000000 | J7: 0 | L7: =SUM(Report!G7:J7) -> 870000000 | M7: =SUM(Installments!B7:R7) -> 430003000 | N7: =L7-M7 -> 439997000 | O7: =Report!G7-Installments!U7 -> 106997000 | P7: =Report!H7-Installments!V7 -> 293000000
F8: مهر | G8: 460000000 | H8: 370000000 | I8: 40000000 | J8: 0 | L8: =SUM(Report!G8:J8) -> 870000000 | M8: =SUM(Installments!B8:R8) -> 634140000 | N8: =L8-M8 -> 235860000 | O8: =Report!G8-Installments!U8 -> -97140000 | P8: =Report!H8-Installments!V8 -> 293000000
F9: آبان | G9: 460000000 | H9: 370000000 | I9: 40000000 | J9: 0 | L9: =SUM(Report!G9:J9) -> 870000000 | M9: =SUM(Installments!B9:R9) -> 526863000 | N9: =L9-M9 -> 343137000 | O9: =Report!G9-Installments!U9 -> -14863000 | P9: =Report!H9-Installments!V9 -> 318000000
F10: آذر | G10: 460000000 | H10: 370000000 | I10: 40000000 | J10: 0 | L10: =SUM(Report!G10:J10) -> 870000000 | M10: =SUM(Installments!B10:R10) -> 514863000 | N10: =L10-M10 -> 355137000 | O10: =Report!G10-Installments!U10 -> -14863000 | P10: =Report!H10-Installments!V10 -> 330000000
F11: دی | G11: 460000000 | H11: 370000000 | I11: 40000000 | J11: 0 | L11: =SUM(Report!G11:J11) -> 870000000 | M11: =SUM(Installments!B11:R11) -> 514863000 | N11: =L11-M11 -> 355137000 | O11: =Report!G11-Installments!U11 -> -14863000 | P11: =Report!H11-Installments!V11 -> 330000000
F12: بهمن | G12: 460000000 | H12: 370000000 | I12: 40000000 | J12: 0 | L12: =SUM(Report!G12:J12) -> 870000000 | M12: =SUM(Installments!B12:R12) -> 514863000 | N12: =L12-M12 -> 355137000 | O12: =Report!G12-Installments!U12 -> -14863000 | P12: =Report!H12-Installments!V12 -> 330000000
F13: اسفند | G13: 460000000 | H13: 370000000 | I13: 40000000 | J13: 0 | L13: =SUM(Report!G13:J13) -> 870000000 | M13: =SUM(Installments!B13:R13) -> 476363000 | N13: =L13-M13 -> 393637000 | O13: =Report!G13-Installments!U13 -> 23637000 | P13: =Report!H13-Installments!V13 -> 330000000
